<mujocoinclude>
    <actuator>
        <!-- Physical limits of the actuator. -->
        <motor joint="joint1" name="torq_j1"/>
        <motor joint="joint2" name="torq_j2"/>
        <motor joint="joint3" name="torq_j3"/>
        <motor joint="joint4" name="torq_j4"/>
        <motor joint="joint5" name="torq_j5"/>
        <motor joint="joint6" name="torq_j6"/>
    </actuator>
    <asset>
        <mesh name="link0" file="meshes_ur5e/base.stl" />
        <mesh name="link1" file="meshes_ur5e/shoulder.stl" />
        <mesh name="link2" file="meshes_ur5e/upperarm.stl" />
        <mesh name="link3" file="meshes_ur5e/forearm.stl" />
        <mesh name="link4" file="meshes_ur5e/wrist1.stl" />
        <mesh name="link5" file="meshes_ur5e/wrist2.stl" />
        <mesh name="link6" file="meshes_ur5e/wrist3.stl" />
        <mesh name="link0_vis" file="meshes_ur5e/base_vis.stl" />
        <mesh name="link1_vis" file="meshes_ur5e/shoulder_vis.stl" />
        <mesh name="link2_vis" file="meshes_ur5e/upperarm_vis.stl" />
        <mesh name="link3_vis" file="meshes_ur5e/forearm_vis.stl" />
        <mesh name="link4_vis" file="meshes_ur5e/wrist1_vis.stl" />
        <mesh name="link5_vis" file="meshes_ur5e/wrist2_vis.stl" />
        <mesh name="link6_vis" file="meshes_ur5e/wrist3_vis.stl" />
        <mesh name="finger" file="meshes_ur5e/robotiq_fts300.stl" />
        
    </asset>
    <worldbody>
        <body name="base" pos="-0.5 -0.1 0">
            <camera name="robotview" pos="1 0 0.4" quat="0.653 0.271 0.271 0.653"/>
            <body name="link0" pos="0 0 0">
                <geom name="link0_visual" type="mesh" contype="0" conaffinity="0" group="1" rgba="1 1 1 1" mesh="link0_vis"/>
                <geom name="link0_collision" type="mesh" rgba="0 0.5 0 1" mesh="link0"/>
                <body name="link1" pos="0 0 0.333">
                    <joint name="joint1" pos="0 0 0" axis="0 0 1" limited="true" range="-2.8973 2.8973"/>
                    <geom name="link1_visual" type="mesh" contype="0" conaffinity="0" group="1" rgba="1 1 1 1" mesh="link1_vis"/>
                    <geom name="link1_collision" type="mesh" rgba="0 0.5 0 1" mesh="link1"/>
                    <body name="link2" pos="0 0 0" quat="0.707107 -0.707107 0 0">
                        <joint name="joint2" pos="0 0 0" axis="0 0 1" limited="true" range="-1.7628 1.7628"/>
                        <geom name="link2_visual" type="mesh" contype="0" conaffinity="0" group="1" rgba="1 1 1 1" mesh="link2_vis"/>
                        <geom name="link2_collision" type="mesh" rgba="0 0.5 0 1" mesh="link2"/>
                        <body name="link3" pos="0 -0.316 0" quat="0.707107 0.707107 0 0">
                            <joint name="joint3" pos="0 0 0" axis="0 0 1" limited="true" range="-2.8973 2.8973"/>
                            <geom name="link3_visual" type="mesh" contype="0" conaffinity="0" group="1" rgba="1 1 1 1" mesh="link3_vis"/>
                            <geom name="link3_collision" type="mesh" rgba="0 0.5 0 1" mesh="link3"/>
                            <body name="link4" pos="0.0825 0 0" quat="0.707107 0.707107 0 0">
                                <joint name="joint4" pos="0 0 0" axis="0 0 1" limited="true" range="-3.0718 -0.0698"/>
                                <geom name="link4_visual" type="mesh" contype="0" conaffinity="0" group="1" rgba="1 1 1 1" mesh="link4_vis"/>
                                <geom name="link4_collision" type="mesh" rgba="0 0.5 0 1" mesh="link4"/>
                                <body name="link5" pos="-0.0825 0.384 0" quat="0.707107 -0.707107 0 0">
                                    <joint name="joint5" pos="0 0 0" axis="0 0 1" limited="true" range="-2.8973 2.8973"/>
                                    <geom name="link5_visual" type="mesh" contype="0" conaffinity="0" group="1" rgba="1 1 1 1" mesh="link5_vis"/>
                                    <geom name="link5_collision" type="mesh" rgba="0 0.5 0 1" mesh="link5"/>
                                    <body name="link6" pos="0 0 0" quat="0.707107 0.707107 0 0">
                                        <joint name="joint6" pos="0 0 0" axis="0 0 1" limited="true" range="-0.0175 3.7525"/>
                                        <geom name="link6_visual" type="mesh" contype="0" conaffinity="0" group="1" rgba="1 1 1 1" mesh="link6_vis"/>
                                        <geom name="link6_collision" type="mesh" rgba="0 0.5 0 1" mesh="link6"/>
                                        <body name="finger" pos="0 0 0.1065" quat="0.923785 0 0 -0.382911">
                                                <geom name="finger" quat="0 0 0 1" type="mesh" contype="0" conaffinity="0" group="1" rgba="0 0 0 1" mesh="finger"/>
                                        </body>
                                    </body>
                                </body>
                            </body>
                        </body>
                    </body>
                </body>
            </body>
        </body>
    </worldbody>
</mujocoinclude>
